{
 "xsize": 16,
 "zsize": 16,
 "slices": [
  [
   "                ",
   " ⑬⑬⑬⑬⑬⑬⑬⑬⑬⑬⑬⑬   ",
   " ⑬⑬⑬⑬⑬⑬⑬⑬⑬⑬⑬⑬   ",
   " ⑬⑬⑬⑬⑬⑬⑬⑬⑬⑬⑬⑬   ",
   " ⑬⑬⑬⑬⑬⑬⑬⑬⑬⑬⑬⑬   ",
   " ⑬⑬⑬⑬⑬⑬⑬⑬⑬⑬⑬⑬   ",
   " ⑬⑬⑬⑬⑬⑬⑬⑬⑬⑬⑬⑬   ",
   " ⑬⑬⑬⑬⑬⑬⑬⑬⑬⑬⑬⑬   ",
   " ⑬⑬⑬⑬⑬⑬⑬⑬⑬⑬⑬⑬   ",
   " ⑬⑬⑬⑬⑬⑬⑬⑬⑬⑬⑬⑬   ",
   " ⑬⑬⑬⑬⑬⑬⑬⑬⑬⑬⑬⑬   ",
   " ⑬⑬⑬⑬⑬⑬⑬⑬⑬⑬⑬⑬   ",
   " ⑬⑬⑬⑬⑬⑬⑬⑬⑬⑬⑬⑬   ",
   " ⑬⑬⑬⑬⑬⑬⑬⑬⑬⑬⑬⑬   ",
   " ⑬⑬⑬⑬⑬⑬⑬⑬⑬⑬⑬⑬   ",
   "                "
  ],
  [
   "                ",
   " ③③③③③③③③③③③③   ",
   " ③  一一   丁 ③   ",
   " ③丂丂       ③   ",
   " ③ 丂丂      七③   ",
   " ③ 丄        ③   ",
   " ③ 丂丂    一  ③   ",
   " ③一丂丂  一一   ③   ",
   " ③          ③   ",
   " ③          ③   ",
   " ③  丅       ③   ",
   " ③⑪⑪⑪    一丆一③   ",
   " ③⑪ 万  丆    ③   ",
   " ③⑪⑪⑪    丆 丅③   ",
   " ③③③③③③③③③③③③   ",
   "                "
  ],
  [
   "                ",
   "                ",
   "          丈     ",
   "   三三           ",
   "   三三           ",
   "   丄            ",
   "   三三           ",
   "   三三           ",
   "                ",
   "                ",
   "    丄           ",
   "  ⑪⑪⑪           ",
   "  ⑪上下           ",
   "  ⑪⑪⑪           ",
   "                ",
   "                "
  ],
  [
   "                ",
   "                ",
   "          丈     ",
   "                ",
   "                ",
   "                ",
   "                ",
   "                ",
   "                ",
   "                ",
   "    丄           ",
   "  ⑪⑪⑪           ",
   "  ⑪丌⑪           ",
   "  ⑪⑪⑪           ",
   "                ",
   "                "
  ],
  [
   "                ",
   "                ",
   "          不     ",
   "                ",
   "                ",
   "                ",
   "                ",
   "                ",
   "                ",
   "                ",
   "                ",
   "  ⑪⑪⑪           ",
   "  ⑪⑪⑪           ",
   "  ⑪⑪⑪           ",
   "                ",
   "                "
  ],
  [
   "                ",
   "                ",
   "                ",
   "                ",
   "                ",
   "                ",
   "                ",
   "                ",
   "                ",
   "                ",
   "                ",
   "                ",
   "                ",
   "                ",
   "                ",
   "                "
  ]
 ],
 "palette": {
  "palette": [
   {
    "char": "一",
    "block": "minecraft:moss_carpet"
   },
   {
    "char": "丁",
    "block": "minecraft:iron_bars[north=true,south=false,east=false,west=false]"
   },
   {
    "char": "丂",
    "block": "minecraft:light_blue_concrete"
   },
   {
    "char": "七",
    "block": "immersive_weathering:ivy[down=false,east=true,north=false,south=false,up=false,west=false]"
   },
   {
    "char": "丄",
    "block": "minecraft:vine[south=true]"
   },
   {
    "char": "丅",
    "block": "immersive_weathering:ivy[down=false,east=false,north=false,south=true,up=false,west=false]"
   },
   {
    "char": "丆",
    "blocks": [
     {
      "random": 32,
      "block": "zc_world:trash_bags"
     },
     {
      "random": 26,
      "block": "minecraft:moss_carpet"
     },
     {
      "random": 26,
      "block": "createdeco:industrial_iron_hull[facing=up]"
     },
     {
      "random": 26,
      "block": "minecraft:cauldron"
     },
     {
      "random": 1000,
      "block": "refurbished_furniture:white_stool"
     }
    ]
   },
   {
    "char": "万",
    "block": "minecraft:iron_door[facing=east,half=lower,hinge=left,open=false]"
   },
   {
    "char": "丈",
    "block": "minecraft:iron_bars[north=false,south=false,east=false,west=false]"
   },
   {
    "char": "三",
    "block": "minecraft:smooth_stone_slab[type=bottom]"
   },
   {
    "char": "上",
    "block": "immersive_weathering:ivy[down=false,east=false,north=false,south=false,up=false,west=true]"
   },
   {
    "char": "下",
    "block": "minecraft:iron_door[facing=east,half=upper,hinge=left,open=false]"
   },
   {
    "char": "丌",
    "block": "minecraft:vine[west=true]"
   },
   {
    "char": "不",
    "block": "minecraft:lightning_rod"
   },
   {
    "char": "",
    "block": "comforts:sleeping_bag_light_gray[facing=north,part=head]"
   },
   {
    "char": "",
    "block": "comforts:sleeping_bag_light_gray[facing=north,part=foot]"
   }
  ]
 }
}