{
 "xsize": 16,
 "zsize": 16,
 "slices": [
  [
   "                ",
   "                ",
   "                ",
   " ⑬⑬⑬⑬⑬⑬⑬⑬⑬⑬⑬⑬⑬⑬ ",
   " ⑬⑬⑬⑬⑬⑬⑬⑬⑬⑬⑬⑬⑬⑬ ",
   " ⑬⑬⑬⑬⑬⑬⑬⑬⑬⑬⑬⑬⑬⑬ ",
   " ⑬⑬⑬⑬⑬⑬⑬⑬⑬⑬⑬⑬⑬⑬ ",
   " ⑬⑬⑬⑬⑬⑬⑬⑬⑬⑬⑬⑬⑬⑬ ",
   " ⑬⑬⑬⑬⑬⑬⑬⑬⑬⑬⑬⑬⑬⑬ ",
   " ⑬⑬⑬⑬⑬⑬⑬⑬⑬⑬⑬⑬⑬⑬ ",
   " ⑬⑬⑬⑬⑬⑬⑬⑬⑬⑬⑬⑬⑬⑬ ",
   " ⑬⑬⑬⑬⑬⑬⑬⑬⑬⑬⑬⑬⑬⑬ ",
   " ⑬⑬⑬⑬⑬⑬⑬⑬⑬⑬⑬⑬⑬⑬ ",
   " ⑬⑬⑬⑬⑬⑬⑬⑬⑬⑬⑬⑬⑬⑬ ",
   " ⑬⑬⑬⑬⑬⑬⑬⑬⑬⑬⑬⑬⑬⑬ ",
   "                "
  ],
  [
   "                ",
   "                ",
   "                ",
   " ③③③③③③③③③③③③③③ ",
   " ③  一      丁 丂③ ",
   " ③七        丄  ③ ",
   " ③    丁    丁 丄③ ",
   " ③     丁      ③ ",
   " ③     丁    丄 ③ ",
   " ③丁           ③ ",
   " ③丁           ③ ",
   " ③ 丅丅 丅丅  丂⑪丆⑪③ ",
   " ③丅丅万丅丅   ⑪ ⑪③ ",
   " ③    丁   ⑪⑪⑪③ ",
   " ③③③③③③③③③③③③③③ ",
   "                "
  ],
  [
   "                ",
   "                ",
   "                ",
   "                ",
   "                ",
   "  丈             ",
   "                ",
   "                ",
   "                ",
   "                ",
   "                ",
   "   三三 三三  万⑪上⑪  ",
   "   三三万三三   ⑪下⑪  ",
   "           ⑪⑪⑪  ",
   "                ",
   "                "
  ],
  [
   "                ",
   "                ",
   "                ",
   "                ",
   "                ",
   "  丈             ",
   "                ",
   "                ",
   "                ",
   "                ",
   "                ",
   "          万⑪⑪⑪  ",
   "           ⑪丌⑪  ",
   "           ⑪⑪⑪  ",
   "                ",
   "                "
  ],
  [
   "                ",
   "                ",
   "                ",
   "                ",
   "                ",
   "  不             ",
   "                ",
   "                ",
   "                ",
   "                ",
   "                ",
   "           ⑪⑪⑪  ",
   "           ⑪⑪⑪  ",
   "           ⑪⑪⑪  ",
   "                ",
   "                "
  ],
  [
   "                ",
   "                ",
   "                ",
   "                ",
   "                ",
   "                ",
   "                ",
   "                ",
   "                ",
   "                ",
   "                ",
   "                ",
   "                ",
   "                ",
   "                ",
   "                "
  ]
 ],
 "palette": {
  "palette": [
   {
    "char": "一",
    "block": "immersive_weathering:ivy[down=false,east=false,north=true,south=false,up=false,west=false]"
   },
   {
    "char": "丁",
    "block": "minecraft:moss_carpet"
   },
   {
    "char": "丂",
    "block": "immersive_weathering:ivy[down=false,east=true,north=false,south=false,up=false,west=false]"
   },
   {
    "char": "七",
    "block": "minecraft:iron_bars[north=false,south=false,east=false,west=true]"
   },
   {
    "char": "丄",
    "blocks": [
     {
      "random": 32,
      "block": "zc_world:trash_bags"
     },
     {
      "random": 26,
      "block": "minecraft:moss_carpet"
     },
     {
      "random": 26,
      "block": "createdeco:industrial_iron_hull[facing=up]"
     },
     {
      "random": 26,
      "block": "minecraft:cauldron"
     },
     {
      "random": 1000,
      "block": "refurbished_furniture:white_stool"
     }
    ]
   },
   {
    "char": "丅",
    "block": "minecraft:light_blue_concrete"
   },
   {
    "char": "丆",
    "block": "minecraft:iron_door[facing=north,half=lower,hinge=left,open=false]"
   },
   {
    "char": "万",
    "block": "minecraft:vine[east=true]"
   },
   {
    "char": "丈",
    "block": "minecraft:iron_bars[north=false,south=false,east=false,west=false]"
   },
   {
    "char": "三",
    "block": "minecraft:smooth_stone_slab[type=bottom]"
   },
   {
    "char": "上",
    "block": "minecraft:iron_door[facing=north,half=upper,hinge=left,open=false]"
   },
   {
    "char": "下",
    "block": "immersive_weathering:ivy[down=false,east=false,north=false,south=true,up=false,west=false]"
   },
   {
    "char": "丌",
    "block": "minecraft:vine[south=true]"
   },
   {
    "char": "不",
    "block": "minecraft:lightning_rod"
   },
   {
    "char": "",
    "block": "comforts:sleeping_bag_purple[facing=south,part=head]"
   },
   {
    "char": "",
    "block": "comforts:sleeping_bag_purple[facing=south,part=foot]"
   }
  ]
 }
}