{
 "xsize": 16,
 "zsize": 16,
 "slices": [
  [
   "             一  ",
   " ⑬⑬⑬⑬⑬⑬⑬⑬⑬⑬⑬⑬⑬⑬ ",
   " ⑬⑬⑬⑬⑬⑬⑬⑬⑬⑬⑬⑬⑬⑬ ",
   " ⑬⑬⑬⑬⑬⑬⑬⑬⑬⑬⑬⑬⑬⑬ ",
   " ⑬⑬⑬⑬⑬⑬⑬⑬⑬⑬⑬⑬⑬⑬ ",
   " ⑬⑬⑬⑬⑬⑬⑬⑬⑬⑬⑬⑬⑬⑬ ",
   " ⑬⑬⑬⑬⑬⑬⑬⑬⑬⑬⑬⑬⑬⑬丁",
   " ⑬⑬⑬⑬⑬⑬⑬⑬⑬⑬⑬⑬⑬⑬ ",
   " ⑬⑬⑬⑬⑬⑬⑬⑬⑬⑬⑬⑬⑬⑬丂",
   " ⑬⑬⑬⑬⑬⑬⑬⑬⑬⑬⑬⑬⑬⑬ ",
   " ⑬⑬⑬⑬⑬⑬⑬⑬⑬⑬⑬⑬⑬⑬ ",
   " ⑬⑬⑬⑬⑬⑬⑬⑬⑬⑬⑬⑬⑬⑬ ",
   " ⑬⑬⑬⑬⑬⑬⑬⑬⑬⑬⑬⑬⑬⑬ ",
   " ⑬⑬⑬⑬⑬⑬⑬⑬⑬⑬⑬⑬⑬⑬ ",
   " ⑬⑬⑬⑬⑬⑬⑬⑬⑬⑬⑬⑬⑬⑬ ",
   "                "
  ],
  [
   "             一  ",
   " 七七七七七七七七七七七七七七 ",
   " 七   丄丅丅   七 ",
   " 七丆丆      丆丆 七 ",
   " 七丆丆万   万 丆丆  七 ",
   " 七  一         七 ",
   " 七七七七七七七七丁丅   七丂",
   " 七七七七七七七七     七 ",
   " 七七七七七七七七     七丂",
   " 七七七七七七七七    丅七 ",
   " 七丅    丅      七 ",
   " 七            七 ",
   " 七丆丆丅      丈  七 ",
   " 七丆丆          七 ",
   " 七七七七七七七七七七七七七七 ",
   "                "
  ],
  [
   "                ",
   "                ",
   "                ",
   "  三三      三三    ",
   "  三三      三三    ",
   "  上 上           ",
   " 下七七七七七七七       ",
   "  七七七七七七七       ",
   "  七七七七七七七       ",
   "  七七七七七七七       ",
   "  丌             ",
   "                ",
   "  三三            ",
   "  三三            ",
   "                ",
   "                "
  ],
  [
   "                ",
   "                ",
   "                ",
   "                ",
   "                ",
   "  上             ",
   "  七七七七七七七       ",
   "  七七七七七七七       ",
   "  七七七七七七七       ",
   "  七七七七七七七       ",
   "  丌             ",
   "                ",
   "                ",
   "                ",
   "                ",
   "                "
  ],
  [
   "                ",
   "                ",
   "                ",
   "                ",
   "                ",
   "                ",
   "  ⑬⑬⑬⑬⑬⑬⑬       ",
   "  ⑬⑬⑬⑬⑬⑬⑬       ",
   "  ⑬⑬⑬⑬⑬⑬⑬       ",
   "  ⑬⑬⑬⑬⑬⑬⑬       ",
   "  丌             ",
   "                ",
   "                ",
   "                ",
   "                ",
   "                "
  ],
  [
   "                ",
   "                ",
   "                ",
   "                ",
   "                ",
   "                ",
   "                ",
   "                ",
   "                ",
   "                ",
   "                ",
   "                ",
   "                ",
   "                ",
   "                ",
   "                "
  ]
 ],
 "palette": {
  "palette": [
   {
    "char": "一",
    "block": "minecraft:vine[south=true]"
   },
   {
    "char": "丁",
    "block": "minecraft:vine[west=true]"
   },
   {
    "char": "丂",
    "block": "immersive_weathering:ivy[down=false,east=false,north=false,south=false,up=false,west=true]"
   },
   {
    "char": "七",
    "block": "minecraft:white_concrete"
   },
   {
    "char": "丄",
    "block": "minecraft:vine[north=true]"
   },
   {
    "char": "丅",
    "block": "minecraft:moss_carpet"
   },
   {
    "char": "丆",
    "block": "minecraft:light_blue_concrete"
   },
   {
    "char": "万",
    "blocks": [
     {
      "random": 32,
      "block": "zc_world:trash_bags"
     },
     {
      "random": 26,
      "block": "minecraft:moss_carpet"
     },
     {
      "random": 26,
      "block": "createdeco:industrial_iron_hull[facing=up]"
     },
     {
      "random": 26,
      "block": "minecraft:cauldron"
     },
     {
      "random": 1000,
      "block": "refurbished_furniture:white_stool"
     }
    ]
   },
   {
    "char": "丈",
    "block": "minecraft:lightning_rod"
   },
   {
    "char": "三",
    "block": "minecraft:smooth_stone_slab[type=bottom]"
   },
   {
    "char": "上",
    "block": "immersive_weathering:ivy[down=false,east=false,north=false,south=true,up=false,west=false]"
   },
   {
    "char": "下",
    "block": "minecraft:vine[east=true]"
   },
   {
    "char": "丌",
    "block": "immersive_weathering:ivy[down=false,east=false,north=true,south=false,up=false,west=false]"
   },
   {
    "char": "",
    "block": "comforts:sleeping_bag_purple[facing=west,part=head]"
   },
   {
    "char": "",
    "block": "comforts:sleeping_bag_purple[facing=west,part=foot]"
   },
   {
    "char": "",
    "block": "comforts:sleeping_bag_green[facing=north,part=head]"
   },
   {
    "char": "",
    "block": "comforts:sleeping_bag_green[facing=north,part=foot]"
   }
  ]
 }
}