{
 "xsize": 16,
 "zsize": 16,
 "slices": [
  [
   "                ",
   "   ⑬⑬⑬⑬⑬⑬⑬⑬⑬⑬⑬⑬ ",
   "   ⑬⑬⑬⑬⑬⑬⑬⑬⑬⑬⑬⑬ ",
   "   ⑬⑬⑬⑬⑬⑬⑬⑬⑬⑬⑬⑬ ",
   "   ⑬⑬⑬⑬⑬⑬⑬⑬⑬⑬⑬⑬ ",
   "   ⑬⑬⑬⑬⑬⑬⑬⑬⑬⑬⑬⑬ ",
   "   ⑬⑬⑬⑬⑬⑬⑬⑬⑬⑬⑬⑬ ",
   "   ⑬⑬⑬⑬⑬⑬⑬⑬⑬⑬⑬⑬ ",
   "   ⑬⑬⑬⑬⑬⑬⑬⑬⑬⑬⑬⑬ ",
   "   ⑬⑬⑬⑬⑬⑬⑬⑬⑬⑬⑬⑬ ",
   "   ⑬⑬⑬⑬⑬⑬⑬⑬⑬⑬⑬⑬ ",
   "   ⑬⑬⑬⑬⑬⑬⑬⑬⑬⑬⑬⑬ ",
   "   ⑬⑬⑬⑬⑬⑬⑬⑬⑬⑬⑬⑬ ",
   "   ⑬⑬⑬⑬⑬⑬⑬⑬⑬⑬⑬⑬ ",
   "   ⑬⑬⑬⑬⑬⑬⑬⑬⑬⑬⑬⑬ ",
   "                "
  ],
  [
   "                ",
   "   ③③③③③③③③③③③③ ",
   "   ③一 丁    ⑪⑪⑪③ ",
   "   ③    丁  丂 ⑪③ ",
   "   ③七丁七    ⑪⑪⑪③ ",
   "   ③       一  ③ ",
   "   ③          ③ ",
   "   ③          ③ ",
   "   ③   七七  丄丄七③ ",
   "   ③  七    丄丄 ③ ",
   "   ③        丅 ③ ",
   "   ③丆      丄丄 ③ ",
   "   ③       丄丄③ ",
   "   ③ 万   七七  ③ ",
   "   ③③③③③③③③③③③③ ",
   "                "
  ],
  [
   "                ",
   "                ",
   "           ⑪⑪⑪  ",
   "           丈三⑪  ",
   "           ⑪⑪⑪  ",
   "           丅    ",
   "                ",
   "                ",
   "           上上   ",
   "           上上   ",
   "            丅   ",
   "           上上   ",
   "           上上   ",
   "     下          ",
   "                ",
   "                "
  ],
  [
   "                ",
   "                ",
   "           ⑪⑪⑪  ",
   "           ⑪丌⑪  ",
   "           ⑪⑪⑪  ",
   "           丅    ",
   "                ",
   "                ",
   "                ",
   "                ",
   "                ",
   "                ",
   "                ",
   "     下          ",
   "                ",
   "                "
  ],
  [
   "                ",
   "                ",
   "           ⑪⑪⑪  ",
   "           ⑪⑪⑪  ",
   "           ⑪⑪⑪  ",
   "                ",
   "                ",
   "                ",
   "                ",
   "                ",
   "                ",
   "                ",
   "                ",
   "     不          ",
   "                ",
   "                "
  ],
  [
   "                ",
   "                ",
   "                ",
   "                ",
   "                ",
   "                ",
   "                ",
   "                ",
   "                ",
   "                ",
   "                ",
   "                ",
   "                ",
   "                ",
   "                ",
   "                "
  ]
 ],
 "palette": {
  "palette": [
   {
    "char": "一",
    "block": "immersive_weathering:ivy[down=false,east=false,north=true,south=false,up=false,west=false]"
   },
   {
    "char": "丁",
    "blocks": [
     {
      "random": 32,
      "block": "zc_world:trash_bags"
     },
     {
      "random": 26,
      "block": "minecraft:moss_carpet"
     },
     {
      "random": 26,
      "block": "createdeco:industrial_iron_hull[facing=up]"
     },
     {
      "random": 26,
      "block": "minecraft:cauldron"
     },
     {
      "random": 1000,
      "block": "refurbished_furniture:white_stool"
     }
    ]
   },
   {
    "char": "丂",
    "block": "minecraft:iron_door[facing=west,half=lower,hinge=left,open=false]"
   },
   {
    "char": "七",
    "block": "minecraft:moss_carpet"
   },
   {
    "char": "丄",
    "block": "minecraft:light_blue_concrete"
   },
   {
    "char": "丅",
    "block": "minecraft:vine[north=true]"
   },
   {
    "char": "丆",
    "block": "immersive_weathering:ivy[down=false,east=false,north=false,south=false,up=false,west=true]"
   },
   {
    "char": "万",
    "block": "minecraft:iron_bars[north=false,south=true,east=false,west=false]"
   },
   {
    "char": "丈",
    "block": "minecraft:iron_door[facing=west,half=upper,hinge=left,open=false]"
   },
   {
    "char": "三",
    "block": "immersive_weathering:ivy[down=false,east=true,north=false,south=false,up=false,west=false]"
   },
   {
    "char": "上",
    "block": "minecraft:smooth_stone_slab[type=bottom]"
   },
   {
    "char": "下",
    "block": "minecraft:iron_bars[north=false,south=false,east=false,west=false]"
   },
   {
    "char": "丌",
    "block": "minecraft:vine[east=true]"
   },
   {
    "char": "不",
    "block": "minecraft:lightning_rod"
   },
   {
    "char": "",
    "block": "comforts:sleeping_bag_blue[facing=south,part=head]"
   },
   {
    "char": "",
    "block": "comforts:sleeping_bag_blue[facing=south,part=foot]"
   }
  ]
 }
}