{
 "xsize": 16,
 "zsize": 16,
 "slices": [
  [
   "                ",
   " ⑬⑬⑬⑬⑬⑬⑬⑬⑬⑬⑬⑬⑬⑬ ",
   " ⑬⑬⑬⑬⑬⑬⑬⑬⑬⑬⑬⑬⑬⑬ ",
   " ⑬⑬⑬⑬⑬⑬⑬⑬⑬⑬⑬⑬⑬⑬ ",
   " ⑬⑬⑬⑬⑬⑬⑬⑬⑬⑬⑬⑬⑬⑬ ",
   " ⑬⑬⑬⑬⑬⑬⑬⑬⑬⑬⑬⑬⑬⑬ ",
   " ⑬⑬⑬⑬⑬⑬⑬⑬⑬⑬⑬⑬⑬⑬ ",
   " ⑬⑬⑬⑬⑬⑬⑬⑬⑬⑬⑬⑬⑬⑬ ",
   " ⑬⑬⑬⑬⑬⑬⑬⑬⑬⑬⑬⑬⑬⑬ ",
   " ⑬⑬⑬⑬⑬⑬⑬⑬⑬⑬⑬⑬⑬⑬ ",
   " ⑬⑬⑬⑬⑬⑬⑬⑬⑬⑬⑬⑬⑬⑬ ",
   " ⑬⑬⑬⑬⑬⑬⑬⑬⑬⑬⑬⑬⑬⑬ ",
   " ⑬⑬⑬⑬⑬⑬⑬⑬⑬⑬⑬⑬⑬⑬ ",
   " ⑬⑬⑬⑬⑬⑬⑬⑬⑬⑬⑬⑬⑬⑬一",
   " ⑬⑬⑬⑬⑬⑬⑬⑬⑬⑬⑬⑬⑬⑬ ",
   "       丁 丂      "
  ],
  [
   "                ",
   " 七七七七七七七七七七七七七七 ",
   " 七丄丄 丅七七七七 丄丄七 ",
   " 七丄丄  七七七七 丄丄七 ",
   " 七 丅  七七七七一丆  七 ",
   " 七    七七七七    七 ",
   " 七    七七七七    七 ",
   " 七   丅七七七七   万七 ",
   " 七    七七七七 丆 丅七 ",
   " 七       丂   丅七 ",
   " 七       丅 丄丄 七 ",
   " 七 丈       丄丄 七 ",
   " 七           七 ",
   " 七   丅       七一",
   " 七七七七七七七七七七七七七七 ",
   "       丁 丁      "
  ],
  [
   "                ",
   "         三      ",
   "  上上 下七七七七丌上上   ",
   "  上上  七七七七 上上   ",
   "      七七七七丌     ",
   "      七七七七      ",
   "      七七七七      ",
   "      七七七七      ",
   "      七七七七      ",
   "                ",
   "           上上   ",
   "           上上   ",
   "                ",
   "                ",
   "                ",
   "                "
  ],
  [
   "                ",
   "                ",
   "     下七七七七丌     ",
   "      七七七七      ",
   "      七七七七      ",
   "      七七七七      ",
   "      七七七七      ",
   "      七七七七      ",
   "      七七七七      ",
   "                ",
   "                ",
   "                ",
   "                ",
   "                ",
   "                ",
   "                "
  ],
  [
   "                ",
   "                ",
   "     下⑬⑬⑬⑬      ",
   "      ⑬⑬⑬⑬      ",
   "      ⑬⑬⑬⑬      ",
   "      ⑬⑬⑬⑬      ",
   "      ⑬⑬⑬⑬      ",
   "      ⑬⑬⑬⑬      ",
   "      ⑬⑬⑬⑬      ",
   "                ",
   "                ",
   "                ",
   "                ",
   "                ",
   "                ",
   "                "
  ],
  [
   "                ",
   "                ",
   "                ",
   "                ",
   "                ",
   "                ",
   "                ",
   "                ",
   "                ",
   "                ",
   "                ",
   "                ",
   "                ",
   "                ",
   "                ",
   "                "
  ]
 ],
 "palette": {
  "palette": [
   {
    "char": "一",
    "block": "minecraft:vine[west=true]"
   },
   {
    "char": "丁",
    "block": "immersive_weathering:ivy[down=false,east=false,north=true,south=false,up=false,west=false]"
   },
   {
    "char": "丂",
    "block": "minecraft:vine[north=true]"
   },
   {
    "char": "七",
    "block": "minecraft:white_concrete"
   },
   {
    "char": "丄",
    "block": "minecraft:light_blue_concrete"
   },
   {
    "char": "丅",
    "block": "minecraft:moss_carpet"
   },
   {
    "char": "丆",
    "blocks": [
     {
      "random": 32,
      "block": "zc_world:trash_bags"
     },
     {
      "random": 26,
      "block": "minecraft:moss_carpet"
     },
     {
      "random": 26,
      "block": "createdeco:industrial_iron_hull[facing=up]"
     },
     {
      "random": 26,
      "block": "minecraft:cauldron"
     },
     {
      "random": 1000,
      "block": "refurbished_furniture:white_stool"
     }
    ]
   },
   {
    "char": "万",
    "block": "minecraft:vine[east=true]"
   },
   {
    "char": "丈",
    "block": "minecraft:lightning_rod"
   },
   {
    "char": "三",
    "block": "minecraft:vine[south=true]"
   },
   {
    "char": "上",
    "block": "minecraft:smooth_stone_slab[type=bottom]"
   },
   {
    "char": "下",
    "block": "immersive_weathering:ivy[down=false,east=true,north=false,south=false,up=false,west=false]"
   },
   {
    "char": "丌",
    "block": "immersive_weathering:ivy[down=false,east=false,north=false,south=false,up=false,west=true]"
   },
   {
    "char": "",
    "block": "comforts:sleeping_bag_orange[facing=north,part=head]"
   },
   {
    "char": "",
    "block": "comforts:sleeping_bag_orange[facing=north,part=foot]"
   },
   {
    "char": "",
    "block": "comforts:sleeping_bag_light_gray[facing=south,part=head]"
   },
   {
    "char": "",
    "block": "comforts:sleeping_bag_light_gray[facing=south,part=foot]"
   }
  ]
 }
}