{
 "xsize": 16,
 "zsize": 16,
 "slices": [
  [
   "      一 丁       ",
   " ⑬⑬⑬⑬⑬⑬⑬⑬⑬⑬⑬⑬⑬⑬ ",
   "丂⑬⑬⑬⑬⑬⑬⑬⑬⑬⑬⑬⑬⑬⑬ ",
   " ⑬⑬⑬⑬⑬⑬⑬⑬⑬⑬⑬⑬⑬⑬ ",
   " ⑬⑬⑬⑬⑬⑬⑬⑬⑬⑬⑬⑬⑬⑬ ",
   " ⑬⑬⑬⑬⑬⑬⑬⑬⑬⑬⑬⑬⑬⑬ ",
   " ⑬⑬⑬⑬⑬⑬⑬⑬⑬⑬⑬⑬⑬⑬ ",
   " ⑬⑬⑬⑬⑬⑬⑬⑬⑬⑬⑬⑬⑬⑬ ",
   " ⑬⑬⑬⑬⑬⑬⑬⑬⑬⑬⑬⑬⑬⑬ ",
   " ⑬⑬⑬⑬⑬⑬⑬⑬⑬⑬⑬⑬⑬⑬ ",
   " ⑬⑬⑬⑬⑬⑬⑬⑬⑬⑬⑬⑬⑬⑬ ",
   " ⑬⑬⑬⑬⑬⑬⑬⑬⑬⑬⑬⑬⑬⑬ ",
   " ⑬⑬⑬⑬⑬⑬⑬⑬⑬⑬⑬⑬⑬⑬ ",
   " ⑬⑬⑬⑬⑬⑬⑬⑬⑬⑬⑬⑬⑬⑬ ",
   " ⑬⑬⑬⑬⑬⑬⑬⑬⑬⑬⑬⑬⑬⑬ ",
   "                "
  ],
  [
   "      丁 丁       ",
   " 七七七七七七七七七七七七七七 ",
   "丂七      丄   七 ",
   " 七          七 ",
   " 七 丅丅       丆 七 ",
   " 七 丅丅 丄       七 ",
   " 七丄   一       七 ",
   " 七丄 万 七七七七    七 ",
   " 七丈   七七七七丄   七 ",
   " 七    七七七七    七 ",
   " 七    七七七七    七 ",
   " 七  万丂七七七七  丄 七 ",
   " 七 丅丅 七七七七  丅丅七 ",
   " 七 丅丅 七七七七丄 丅丅七 ",
   " 七七七七七七七七七七七七七七 ",
   "                "
  ],
  [
   "                ",
   "                ",
   "                ",
   "                ",
   "   三三           ",
   "   三三           ",
   "                ",
   "      七七七七      ",
   "      七七七七      ",
   "      七七七七      ",
   "      七七七七      ",
   "     上七七七七      ",
   "   三三 七七七七  三三  ",
   "   三三上七七七七下 三三  ",
   "      丌         ",
   "                "
  ],
  [
   "                ",
   "                ",
   "                ",
   "                ",
   "                ",
   "                ",
   "                ",
   "      七七七七      ",
   "      七七七七      ",
   "      七七七七      ",
   "      七七七七      ",
   "      七七七七      ",
   "      七七七七      ",
   "     上七七七七下     ",
   "                ",
   "                "
  ],
  [
   "                ",
   "                ",
   "                ",
   "                ",
   "                ",
   "                ",
   "                ",
   "      ⑬⑬⑬⑬      ",
   "      ⑬⑬⑬⑬      ",
   "      ⑬⑬⑬⑬      ",
   "      ⑬⑬⑬⑬      ",
   "      ⑬⑬⑬⑬      ",
   "      ⑬⑬⑬⑬      ",
   "      ⑬⑬⑬⑬下     ",
   "                ",
   "                "
  ],
  [
   "                ",
   "                ",
   "                ",
   "                ",
   "                ",
   "                ",
   "                ",
   "                ",
   "                ",
   "                ",
   "                ",
   "                ",
   "                ",
   "                ",
   "                ",
   "                "
  ]
 ],
 "palette": {
  "palette": [
   {
    "char": "一",
    "block": "minecraft:vine[south=true]"
   },
   {
    "char": "丁",
    "block": "immersive_weathering:ivy[down=false,east=false,north=false,south=true,up=false,west=false]"
   },
   {
    "char": "丂",
    "block": "minecraft:vine[east=true]"
   },
   {
    "char": "七",
    "block": "minecraft:white_concrete"
   },
   {
    "char": "丄",
    "block": "minecraft:moss_carpet"
   },
   {
    "char": "丅",
    "block": "minecraft:light_blue_concrete"
   },
   {
    "char": "丆",
    "block": "minecraft:lightning_rod"
   },
   {
    "char": "万",
    "blocks": [
     {
      "random": 32,
      "block": "zc_world:trash_bags"
     },
     {
      "random": 26,
      "block": "minecraft:moss_carpet"
     },
     {
      "random": 26,
      "block": "createdeco:industrial_iron_hull[facing=up]"
     },
     {
      "random": 26,
      "block": "minecraft:cauldron"
     },
     {
      "random": 1000,
      "block": "refurbished_furniture:white_stool"
     }
    ]
   },
   {
    "char": "丈",
    "block": "minecraft:vine[west=true]"
   },
   {
    "char": "三",
    "block": "minecraft:smooth_stone_slab[type=bottom]"
   },
   {
    "char": "上",
    "block": "immersive_weathering:ivy[down=false,east=true,north=false,south=false,up=false,west=false]"
   },
   {
    "char": "下",
    "block": "immersive_weathering:ivy[down=false,east=false,north=false,south=false,up=false,west=true]"
   },
   {
    "char": "丌",
    "block": "minecraft:vine[north=true]"
   },
   {
    "char": "",
    "block": "comforts:sleeping_bag_gray[facing=north,part=head]"
   },
   {
    "char": "",
    "block": "comforts:sleeping_bag_gray[facing=north,part=foot]"
   },
   {
    "char": "",
    "block": "comforts:sleeping_bag_blue[facing=north,part=head]"
   },
   {
    "char": "",
    "block": "comforts:sleeping_bag_blue[facing=north,part=foot]"
   }
  ]
 }
}