{
  "xsize": 16,
  "zsize": 16,
  "slices": [
    [
      "一一一一一一一一一一一一一一一一",
      "一一一一一一一一一一一一一一一一",
      "一一一一一一一一一一一一一一一一",
      "一一一一一一一一一一一一一一一一",
      "一一一一一一一一一一一一一一一一",
      "一一一一一一一一一一一一一一一一",
      "一一一一一一一一一一一一一一一一",
      "一一一一一一一一一一一一一一一一",
      "一一一一一一一一一一一一一一一一",
      "一一一一一一一一一一一一一一一一",
      "一一一一一一一一一一一一一一一一",
      "一一一一一一一一一一一一一一一一",
      "一一一一一一一一一一一一一一一一",
      "一一一一一一一一一一一一一一一一",
      "一一一一一一一一一一一一一一一一",
      "一一一一一一一一一一一一一一一一"
    ],
    [
      "                ",
      "                ",
      "  丁丁丁丁丁丁丁丁丁丁丁丁  ",
      "  丁 丂丂丂丂丂    丁七 ",
      "  丁 丄丅 丆丆    丁  ",
      "  丁 丂丂丂丂丂    丁  ",
      "  丁  万       丁  ",
      "    丈    三      ",
      "          上上上   ",
      "   三 下下   上 上   ",
      "    丌 下   上不上   ",
      "  三     与       ",
      "       下    三   ",
      " 丏丐 丏丐 丏丐 丏丐 丏丐 ",
      "                ",
      "                "
    ],
    [
      "                ",
      "                ",
      "                ",
      "    丂丂丂丂丂     七 ",
      "                ",
      "    丂丂丂丂丂       ",
      "                ",
      "                ",
      "          上上上   ",
      "          上 丑   ",
      "          上丒上   ",
      "          专     ",
      "                ",
      "                ",
      "                ",
      "                "
    ],
    [
      "                ",
      "                ",
      "                ",
      "    丂丂丂丂丂     七 ",
      "    丂丂丂丂丂       ",
      "    丂丂丂丂丂       ",
      "                ",
      "                ",
      "          且且且   ",
      "          且且且   ",
      "          且且且   ",
      "                ",
      "                ",
      "                ",
      "                ",
      "                "
    ],
    [
      "                ",
      "                ",
      "                ",
      "              七 ",
      "                ",
      "                ",
      "                ",
      "                ",
      "                ",
      "                ",
      "                ",
      "                ",
      "                ",
      "                ",
      "                ",
      "                "
    ],
    [
      "                ",
      "                ",
      "                ",
      "              丕 ",
      "                ",
      "                ",
      "                ",
      "                ",
      "                ",
      "                ",
      "                ",
      "                ",
      "                ",
      "                ",
      "                ",
      "                "
    ]
  ],
  "palette": {
    "palette": [
      {
        "char": "一",
        "blocks": [
          {
            "random": 102,
            "block": "zc_world:asphalt"
          },
          {
            "random": 1000,
            "block": "zc_world:asphalt_cracked"
          }
        ]
      },
      {
        "char": "丁",
        "blocks": [
          {
            "random": 96,
            "block": "zc_world:sandbags"
          },
          {
            "random": 1000,
            "block": "zc_world:sandbag_slab[type=bottom]"
          }
        ]
      },
      {
        "char": "丂",
        "block": "minecraft:green_wool"
      },
      {
        "char": "七",
        "block": "create:cut_andesite_wall[north=none,south=none,east=none,west=none,up=true]"
      },
      {
        "char": "丄",
        "block": "minecraft:green_bed[facing=west,part=head]"
      },
      {
        "char": "丅",
        "block": "minecraft:green_bed[facing=west,part=foot]"
      },
      {
        "char": "丆",
        "block": "refurbished_furniture:spruce_crate",
        "loot": "zc_world:loot_military"
      },
      {
        "char": "万",
        "blocks": [
          {
            "random": 70,
            "block": "zc_world:broken_glass"
          },
          {
            "random": 32,
            "block": "zc_world:blood"
          },
          {
            "random": 1000,
            "block": "minecraft:air"
          }
        ]
      },
      {
        "char": "丈",
        "blocks": [
          {
            "random": 45,
            "block": "zc_world:car_spot[facing=east]"
          },
          {
            "random": 1000,
            "block": "minecraft:air"
          }
        ]
      },
      {
        "char": "三",
        "block": "zc_world:litter"
      },
      {
        "char": "上",
        "block": "createdeco:iron_sheet_metal[axis=y]"
      },
      {
        "char": "下",
        "block": "zc_world:blood"
      },
      {
        "char": "丌",
        "block": "minecraft:iron_trapdoor[facing=east,half=bottom,open=false]"
      },
      {
        "char": "不",
        "block": "minecraft:iron_door[facing=south,half=lower,hinge=left,open=false]"
      },
      {
        "char": "与",
        "block": "minecraft:iron_trapdoor[facing=south,half=bottom,open=false]"
      },
      {
        "char": "丏",
        "block": "create:cut_andesite_wall[north=none,south=none,east=low,west=none,up=true]"
      },
      {
        "char": "丐",
        "block": "create:cut_andesite_wall[north=none,south=none,east=none,west=low,up=true]"
      },
      {
        "char": "丑",
        "block": "minecraft:glass_pane[north=true,south=true,east=false,west=false]",
        "damaged": "minecraft:air"
      },
      {
        "char": "丒",
        "block": "minecraft:iron_door[facing=south,half=upper,hinge=left,open=false]"
      },
      {
        "char": "专",
        "block": "kubejs:sign_bloqueio[facing=south]"
      },
      {
        "char": "且",
        "block": "minecraft:smooth_stone_slab[type=bottom]"
      },
      {
        "char": "丕",
        "block": "createdeco:red_iron_lamp[facing=up,lit=false]"
      }
    ]
  }
}
