{
  "xsize": 16,
  "zsize": 16,
  "slices": [
    [
      "一一一一一一一一一一一一一一一一",
      "一一一一一一一一一一一一一一一一",
      "一一一一一一一一一一一一一一一一",
      "一一一一一一一一一一一一一一一一",
      "一一一一一一一一一一一一一一一一",
      "一一一一一一一一一一一一一一一一",
      "一一一一一一一一一一一一一一一一",
      "一一一一一一一一一一一一一一一一",
      "一一一一一一一一一一一一一一一一",
      "一一一一一一一一一一一一一一一一",
      "一一一一一一一一一一一一一一一一",
      "一一一一一一一一一一一一一一一一",
      "一一一一一一一一一一一一一一一一",
      "一一一一一一一一一一一一一一一一",
      "一一一一一一一一一一一一一一一一",
      "一一一一一一一一一一一一一一一一"
    ],
    [
      "                ",
      "   丁         丂  ",
      "  七七七七七      丄  ",
      "  七     丅丅丅 丆   ",
      "  七     丅 万  丂  ",
      "  七     丅丅丅  丄  ",
      "  七    丆        ",
      "  七丈三丈     上 丂  ",
      "  七丈三丈      下丄  ",
      "  七丈 丈   下下     ",
      "  七丈丌丈不  下   丂  ",
      "  七丈与丈 丏  丐  丄  ",
      "  七      丆      ",
      "  七七七七七    丆 丂  ",
      "             丄  ",
      "                "
    ],
    [
      "                ",
      "   丁            ",
      "                ",
      "        丅丑丅     ",
      "        丅 丒     ",
      "        丅丅丅专    ",
      "                ",
      "   丈 丈          ",
      "   丈 丈          ",
      "   丈 丈          ",
      "   丈 丈          ",
      "   丈 丈          ",
      "                ",
      "                ",
      "                ",
      "                "
    ],
    [
      "                ",
      "   丁            ",
      "                ",
      "        且且且     ",
      "        且且且     ",
      "        且且且     ",
      "                ",
      "   丈丈丈          ",
      "   丈丈丈          ",
      "   丈丈丈          ",
      "   丈丈丈          ",
      "   丈丈丈          ",
      "                ",
      "                ",
      "                ",
      "                "
    ],
    [
      "                ",
      "   丁            ",
      "                ",
      "                ",
      "                ",
      "                ",
      "                ",
      "                ",
      "                ",
      "                ",
      "                ",
      "                ",
      "                ",
      "                ",
      "                ",
      "                "
    ],
    [
      "                ",
      "   丕            ",
      "                ",
      "                ",
      "                ",
      "                ",
      "                ",
      "                ",
      "                ",
      "                ",
      "                ",
      "                ",
      "                ",
      "                ",
      "                ",
      "                "
    ]
  ],
  "palette": {
    "palette": [
      {
        "char": "一",
        "blocks": [
          {
            "random": 102,
            "block": "zc_world:asphalt"
          },
          {
            "random": 1000,
            "block": "zc_world:asphalt_cracked"
          }
        ]
      },
      {
        "char": "丁",
        "block": "create:cut_andesite_wall[north=none,south=none,east=none,west=none,up=true]"
      },
      {
        "char": "丂",
        "block": "create:cut_andesite_wall[north=none,south=low,east=none,west=none,up=true]"
      },
      {
        "char": "七",
        "blocks": [
          {
            "random": 96,
            "block": "zc_world:sandbags"
          },
          {
            "random": 1000,
            "block": "zc_world:sandbag_slab[type=bottom]"
          }
        ]
      },
      {
        "char": "丄",
        "block": "create:cut_andesite_wall[north=low,south=none,east=none,west=none,up=true]"
      },
      {
        "char": "丅",
        "block": "createdeco:iron_sheet_metal[axis=y]"
      },
      {
        "char": "丆",
        "block": "zc_world:litter"
      },
      {
        "char": "万",
        "block": "minecraft:iron_door[facing=east,half=lower,hinge=left,open=false]"
      },
      {
        "char": "丈",
        "block": "minecraft:green_wool"
      },
      {
        "char": "三",
        "block": "refurbished_furniture:spruce_crate",
        "loot": "zc_world:loot_military"
      },
      {
        "char": "上",
        "block": "minecraft:iron_trapdoor[facing=east,half=bottom,open=false]"
      },
      {
        "char": "下",
        "block": "zc_world:blood"
      },
      {
        "char": "丌",
        "block": "minecraft:green_bed[facing=south,part=foot]"
      },
      {
        "char": "不",
        "blocks": [
          {
            "random": 70,
            "block": "zc_world:broken_glass"
          },
          {
            "random": 32,
            "block": "zc_world:blood"
          },
          {
            "random": 1000,
            "block": "minecraft:air"
          }
        ]
      },
      {
        "char": "与",
        "block": "minecraft:green_bed[facing=south,part=head]"
      },
      {
        "char": "丏",
        "blocks": [
          {
            "random": 45,
            "block": "zc_world:car_spot[facing=north]"
          },
          {
            "random": 1000,
            "block": "minecraft:air"
          }
        ]
      },
      {
        "char": "丐",
        "block": "minecraft:iron_trapdoor[facing=north,half=bottom,open=false]"
      },
      {
        "char": "丑",
        "block": "minecraft:glass_pane[north=false,south=false,east=true,west=true]",
        "damaged": "minecraft:air"
      },
      {
        "char": "丒",
        "block": "minecraft:iron_door[facing=east,half=upper,hinge=left,open=false]"
      },
      {
        "char": "专",
        "block": "kubejs:sign_bloqueio[facing=east]"
      },
      {
        "char": "且",
        "block": "minecraft:smooth_stone_slab[type=bottom]"
      },
      {
        "char": "丕",
        "block": "createdeco:red_iron_lamp[facing=up,lit=false]"
      }
    ]
  }
}
