{
  "xsize": 16,
  "zsize": 16,
  "slices": [
    [
      "一一一一一一一一一一一一一一一一",
      "一一一一一一一一一一一一一一一一",
      "一一一一一一一一一一一一一一一一",
      "一一一一一一一一一一一一一一一一",
      "一一一一一一一一一一一一一一一一",
      "一一一一一一一一一一一一一一一一",
      "一一一一一一一一一一一一一一一一",
      "一一一一一一一一一一一一一一一一",
      "一一一一一一一一一一一一一一一一",
      "一一一一一一一一一一一一一一一一",
      "一一一一一一一一一一一一一一一一",
      "一一一一一一一一一一一一一一一一",
      "一一一一一一一一一一一一一一一一",
      "一一一一一一一一一一一一一一一一",
      "一一一一一一一一一一一一一一一一",
      "一一一一一一一一一一一一一一一一"
    ],
    [
      "                ",
      "                ",
      " 丁丂 丁丂 丁丂 丁丂 丁丂 ",
      "   七    丄       ",
      "       丅     七  ",
      "   丆万丆   丄 丈    ",
      "   丆 丆   丄丄 七   ",
      "   丆丆丆          ",
      "      七    三    ",
      "  上       下  上  ",
      "  上    丌丌丌丌丌 上  ",
      "  上    不不 与丏 上  ",
      " 丐上    丌丌丌丌丌 上  ",
      "  上上上上上上上上上上上上  ",
      "                ",
      "                "
    ],
    [
      "                ",
      "                ",
      "                ",
      "                ",
      "     丑          ",
      "   丆丒丆          ",
      "   专 丆          ",
      "   丆丆丆          ",
      "                ",
      "                ",
      "       丌丌丌丌丌    ",
      "                ",
      " 丐     丌丌丌丌丌    ",
      "                ",
      "                ",
      "                "
    ],
    [
      "                ",
      "                ",
      "                ",
      "                ",
      "                ",
      "   且且且          ",
      "   且且且          ",
      "   且且且          ",
      "                ",
      "                ",
      "       丌丌丌丌丌    ",
      "       丌丌丌丌丌    ",
      " 丐     丌丌丌丌丌    ",
      "                ",
      "                ",
      "                "
    ],
    [
      "                ",
      "                ",
      "                ",
      "                ",
      "                ",
      "                ",
      "                ",
      "                ",
      "                ",
      "                ",
      "                ",
      "                ",
      " 丐              ",
      "                ",
      "                ",
      "                "
    ],
    [
      "                ",
      "                ",
      "                ",
      "                ",
      "                ",
      "                ",
      "                ",
      "                ",
      "                ",
      "                ",
      "                ",
      "                ",
      " 丕              ",
      "                ",
      "                ",
      "                "
    ]
  ],
  "palette": {
    "palette": [
      {
        "char": "一",
        "blocks": [
          {
            "random": 102,
            "block": "zc_world:asphalt"
          },
          {
            "random": 1000,
            "block": "zc_world:asphalt_cracked"
          }
        ]
      },
      {
        "char": "丁",
        "block": "create:cut_andesite_wall[north=none,south=none,east=low,west=none,up=true]"
      },
      {
        "char": "丂",
        "block": "create:cut_andesite_wall[north=none,south=none,east=none,west=low,up=true]"
      },
      {
        "char": "七",
        "block": "zc_world:litter"
      },
      {
        "char": "丄",
        "block": "zc_world:blood"
      },
      {
        "char": "丅",
        "block": "minecraft:iron_trapdoor[facing=north,half=bottom,open=false]"
      },
      {
        "char": "丆",
        "block": "createdeco:iron_sheet_metal[axis=y]"
      },
      {
        "char": "万",
        "block": "minecraft:iron_door[facing=north,half=lower,hinge=left,open=false]"
      },
      {
        "char": "丈",
        "block": "minecraft:iron_trapdoor[facing=west,half=bottom,open=false]"
      },
      {
        "char": "三",
        "blocks": [
          {
            "random": 45,
            "block": "zc_world:car_spot[facing=west]"
          },
          {
            "random": 1000,
            "block": "minecraft:air"
          }
        ]
      },
      {
        "char": "上",
        "blocks": [
          {
            "random": 96,
            "block": "zc_world:sandbags"
          },
          {
            "random": 1000,
            "block": "zc_world:sandbag_slab[type=bottom]"
          }
        ]
      },
      {
        "char": "下",
        "blocks": [
          {
            "random": 70,
            "block": "zc_world:broken_glass"
          },
          {
            "random": 32,
            "block": "zc_world:blood"
          },
          {
            "random": 1000,
            "block": "minecraft:air"
          }
        ]
      },
      {
        "char": "丌",
        "block": "minecraft:green_wool"
      },
      {
        "char": "不",
        "block": "refurbished_furniture:spruce_crate",
        "loot": "zc_world:loot_military"
      },
      {
        "char": "与",
        "block": "minecraft:green_bed[facing=east,part=foot]"
      },
      {
        "char": "丏",
        "block": "minecraft:green_bed[facing=east,part=head]"
      },
      {
        "char": "丐",
        "block": "create:cut_andesite_wall[north=none,south=none,east=none,west=none,up=true]"
      },
      {
        "char": "丑",
        "block": "kubejs:sign_bloqueio[facing=north]"
      },
      {
        "char": "丒",
        "block": "minecraft:iron_door[facing=north,half=upper,hinge=left,open=false]"
      },
      {
        "char": "专",
        "block": "minecraft:glass_pane[north=true,south=true,east=false,west=false]",
        "damaged": "minecraft:air"
      },
      {
        "char": "且",
        "block": "minecraft:smooth_stone_slab[type=bottom]"
      },
      {
        "char": "丕",
        "block": "createdeco:red_iron_lamp[facing=up,lit=false]"
      }
    ]
  }
}
