{
  "xsize": 16,
  "zsize": 16,
  "slices": [
    [
      "一一一一一一一一一一一一一一一一",
      "一一一一一一一一一一一一一一一一",
      "一一一一一一一一一一一一一一一一",
      "一一一一一一一一一一一一一一一一",
      "一一一一一一一一一一一一一一一一",
      "一一一一一一一一一一一一一一一一",
      "一一一一一一一一一一一一一一一一",
      "一一一一一一一一一一一一一一一一",
      "一一一一一一一一一一一一一一一一",
      "一一一一一一一一一一一一一一一一",
      "一一一一一一一一一一一一一一一一",
      "一一一一一一一一一一一一一一一一",
      "一一一一一一一一一一一一一一一一",
      "一一一一一一一一一一一一一一一一",
      "一一一一一一一一一一一一一一一一",
      "一一一一一一一一一一一一一一一一"
    ],
    [
      "                ",
      "  丁             ",
      "  丂 七    丄丄丄丄丄  ",
      "      七      丄  ",
      "  丁  丅  丆 万丈万丄  ",
      "  丂   三  上万下万丄  ",
      "     三三   万 万丄  ",
      "  丁三      万丌万丄  ",
      "  丂 不     万丌万丄  ",
      "        七    丄  ",
      "  丁  与与与     丄  ",
      "  丂  丏 与     丄  ",
      "   七 与与与     丄  ",
      "  丁      丄丄丄丄丄  ",
      "  丂         丐   ",
      "                "
    ],
    [
      "                ",
      "                ",
      "                ",
      "                ",
      "          万 万   ",
      "          万 万   ",
      "          万 万   ",
      "          万 万   ",
      "          万 万   ",
      "                ",
      "    丑与与与        ",
      "     丒 与        ",
      "     与专与        ",
      "                ",
      "            丐   ",
      "                "
    ],
    [
      "                ",
      "                ",
      "                ",
      "                ",
      "          万万万   ",
      "          万万万   ",
      "          万万万   ",
      "          万万万   ",
      "          万万万   ",
      "                ",
      "     且且且        ",
      "     且且且        ",
      "     且且且        ",
      "                ",
      "            丐   ",
      "                "
    ],
    [
      "                ",
      "                ",
      "                ",
      "                ",
      "                ",
      "                ",
      "                ",
      "                ",
      "                ",
      "                ",
      "                ",
      "                ",
      "                ",
      "                ",
      "            丐   ",
      "                "
    ],
    [
      "                ",
      "                ",
      "                ",
      "                ",
      "                ",
      "                ",
      "                ",
      "                ",
      "                ",
      "                ",
      "                ",
      "                ",
      "                ",
      "                ",
      "            丕   ",
      "                "
    ]
  ],
  "palette": {
    "palette": [
      {
        "char": "一",
        "blocks": [
          {
            "random": 102,
            "block": "zc_world:asphalt"
          },
          {
            "random": 1000,
            "block": "zc_world:asphalt_cracked"
          }
        ]
      },
      {
        "char": "丁",
        "block": "create:cut_andesite_wall[north=none,south=low,east=none,west=none,up=true]"
      },
      {
        "char": "丂",
        "block": "create:cut_andesite_wall[north=low,south=none,east=none,west=none,up=true]"
      },
      {
        "char": "七",
        "block": "zc_world:litter"
      },
      {
        "char": "丄",
        "blocks": [
          {
            "random": 96,
            "block": "zc_world:sandbags"
          },
          {
            "random": 1000,
            "block": "zc_world:sandbag_slab[type=bottom]"
          }
        ]
      },
      {
        "char": "丅",
        "block": "minecraft:iron_trapdoor[facing=south,half=bottom,open=false]"
      },
      {
        "char": "丆",
        "blocks": [
          {
            "random": 45,
            "block": "zc_world:car_spot[facing=south]"
          },
          {
            "random": 1000,
            "block": "minecraft:air"
          }
        ]
      },
      {
        "char": "万",
        "block": "minecraft:green_wool"
      },
      {
        "char": "丈",
        "block": "minecraft:green_bed[facing=north,part=head]"
      },
      {
        "char": "三",
        "block": "zc_world:blood"
      },
      {
        "char": "上",
        "blocks": [
          {
            "random": 70,
            "block": "zc_world:broken_glass"
          },
          {
            "random": 32,
            "block": "zc_world:blood"
          },
          {
            "random": 1000,
            "block": "minecraft:air"
          }
        ]
      },
      {
        "char": "下",
        "block": "minecraft:green_bed[facing=north,part=foot]"
      },
      {
        "char": "丌",
        "block": "refurbished_furniture:spruce_crate",
        "loot": "zc_world:loot_military"
      },
      {
        "char": "不",
        "block": "minecraft:iron_trapdoor[facing=west,half=bottom,open=false]"
      },
      {
        "char": "与",
        "block": "createdeco:iron_sheet_metal[axis=y]"
      },
      {
        "char": "丏",
        "block": "minecraft:iron_door[facing=west,half=lower,hinge=left,open=false]"
      },
      {
        "char": "丐",
        "block": "create:cut_andesite_wall[north=none,south=none,east=none,west=none,up=true]"
      },
      {
        "char": "丑",
        "block": "kubejs:sign_bloqueio[facing=west]"
      },
      {
        "char": "丒",
        "block": "minecraft:iron_door[facing=west,half=upper,hinge=left,open=false]"
      },
      {
        "char": "专",
        "block": "minecraft:glass_pane[north=false,south=false,east=true,west=true]",
        "damaged": "minecraft:air"
      },
      {
        "char": "且",
        "block": "minecraft:smooth_stone_slab[type=bottom]"
      },
      {
        "char": "丕",
        "block": "createdeco:red_iron_lamp[facing=up,lit=false]"
      }
    ]
  }
}
