{
 "xsize": 16,
 "zsize": 16,
 "slices": [
  [
   "ΑΑΑΑΑΑΑΑΑΑΑΑΑΑΑΑ",
   " ΔΔΔΔΔΔΔΔΔΔΔΔΔΔΑ",
   " ΔΔΔΔΔΔΔΔΔΔΔΔΔΔΑ",
   " ΔΔΔΔΔΔΔΔΔΔΔΔ ΔΑ",
   " ΔΔΔΔΔΔΔΔΔΔΔΔ ΔΑ",
   " ΔΔΔΔΔΔΔΔΔΔΔΔΔΔΑ",
   " ΔΔΔΔΔΔΔΔΔΔΔΔΔΔΑ",
   " ΔΔΔΔΔΔΔΔΔΔΔΔΔΔΑ",
   " ΔΔΔΔΔΔΔΔΔΔΔΔΔΔΑ",
   " ΔΔΔΔΔΔΔΔΔΔΔΔΔΔΑ",
   " ΔΔΔΔΔΔΔΔΔΔΔΔΔΔΑ",
   " ΔΔΔΔΔΔΔΔΔΔΔΔΔΔΑ",
   " ΔΔΔΔΔΔΔΔΔΔΔΔΔΔΑ",
   " ΔΔΔΔΔΔΔΔΔΔΔΔΔΔΑ",
   " ΔΔΔΔΔΔΔΔΔΔΔΔΔΔΑ",
   "               Α"
  ],
  [
   "ΒΑΑΑΑΒΑΑΑΑΒΑΑΑΑΒ",
   "      Ε     ░  Α",
   "      Ε       ΣΑ",
   " ѵ ѵΕ   ░ Ε ϠΑ",
   "    ░       Ε ϠΑ",
   "    ШΕ     ΕϠϠΒ",
   " ΕΕΕΕΕΕ ░   ΕϠϠΑ",
   "             ░ Α",
   "               Α",
   " ΕΕΕΕΕΕ  ΕΕΕΕΕΕΑ",
   "      Ε  Ε    ░Β",
   "               Α",
   " ѵ ѵΕ  Εѵ ѵΑ",
   "      Ε  Ε     Α",
   " ф   Ε ░Εф   Α",
   "               Β"
  ],
  [
   "ΒΓΓΓΓΒΓΓΓΓΒΓΓΓΓΒ",
   "      Ε        Γ",
   "      Ε        Γ",
   "  ѵ  ѵΕ     Ε ΣΓ",
   "            Ε ϠΓ",
   "      Ε     ΕϠϠΒ",
   " ΕΕΕΕΕΕ     ΕϠϠΓ",
   "               Γ",
   "               Γ",
   " ΕΕΕΕΕΕ  ΕΕΕΕΕΕΓ",
   "      Ε  Ε     Β",
   "               Γ",
   "  ѵ  ѵΕ  Ε ѵ  ѵΓ",
   "      Ε  Ε     Γ",
   "      Ε  Ε     Γ",
   "               Β"
  ],
  [
   "ΒΓΓΓΓΒΓΓΓΓΒΓΓΓΓΒ",
   "      Ε     Ε  Γ",
   "      Ε     Ε  Γ",
   "      Ε     Ε  Γ",
   "      Ε     Ε ΣΓ",
   "      Ε     ΕϠϠΒ",
   " ΕΕΕΕΕΕ     ΕϠϠΓ",
   "               Γ",
   "               Γ",
   " ΕΕΕΕΕΕ  ΕΕΕΕΕΕΓ",
   "      Ε  Ε     Β",
   "      Ε  Ε     Γ",
   "      Ε  Ε     Γ",
   "      Ε  Ε     Γ",
   "      Ε  Ε     Γ",
   "               Β"
  ],
  [
   "ΒΑΑΑΑΒΑΑΑΑΒΑΑΑΑΒ",
   "      Ε     Ε  Α",
   "      Ε     Ε  Α",
   "   Ι  Ε   Ι Ε  Α",
   "      Ε     ΕϚ Α",
   "      Ε     Ε  Β",
   " ΕΕΕΕΕΕ     Ε  Α",
   "       Ι       Α",
   "        Ι      Α",
   " ΕΕΕΕΕΕ  ΕΕΕΕΕΕΑ",
   "      Ε  Ε     Β",
   "      Ε  Ε     Α",
   "   Ι  Ε  Ε Ι   Α",
   "      Ε  Ε     Α",
   "      Ε  Ε     Α",
   "               Β"
  ],
  [
   "ΑΑΑΑΑΑΑΑΑΑΑΑΑΑΑΑ",
   " ΔΔΔΔΔΔΔΔΔΔΔΔΔΔΑ",
   " ΔΔΔΔΔΔΔΔΔΔΔΔΔΔΑ",
   " ΔΔΔΔΔΔΔΔΔΔΔΔϚΔΑ",
   " ΔΔΔΔΔΔΔΔΔΔΔΔ  Α",
   " ΔΔΔΔΔΔΔΔΔΔΔΔ  Α",
   " ΔΔΔΔΔΔΔΔΔΔΔΔ  Α",
   " ΔΔΔΔΔΔΔΔΔΔΔΔΔΔΑ",
   " ΔΔΔΔΔΔΔΔΔΔΔΔΔΔΑ",
   " ΔΔΔΔΔΔΔΔΔΔΔΔΔΔΑ",
   " ΔΔΔΔΔΔΔΔΔΔΔΔΔΔΑ",
   " ΔΔΔΔΔΔΔΔΔΔΔΔΔΔΑ",
   " ΔΔΔΔΔΔΔΔΔΔΔΔΔΔΑ",
   " ΔΔΔΔΔΔΔΔΔΔΔΔΔΔΑ",
   " ΔΔΔΔΔΔΔΔΔΔΔΔΔΔΑ",
   "               Α"
  ]
 ],
 "palette": {
  "palette": [
   {
    "char": "",
    "block": "refurbished_furniture:white_basin[facing=south]",
    "damaged": "minecraft:air"
   },
   {
    "char": "",
    "block": "minecraft:chest[facing=west]",
    "loot": "zc_world:loot_house"
   },
   {
    "char": "",
    "block": "hospitals:hospital_bed[facing=south]"
   }
  ]
 }
}