{
 "xsize": 16,
 "zsize": 16,
 "slices": [
  [
   "               Α",
   " ΔΔΔΔΔΔΔΔΔΔΔΔΔΔΑ",
   " ΔΔΔΔΔΔΔΔΔΔΔΔΔΔΑ",
   " ΔΔΔΔΔΔΔΔΔΔΔΔ ΔΑ",
   " ΔΔΔΔΔΔΔΔΔΔΔΔ ΔΑ",
   " ΔΔΔΔΔΔΔΔΔΔΔΔΔΔΑ",
   " ΔΔΔΔΔΔΔΔΔΔΔΔΔΔΑ",
   " ΔΔΔΔΔΔΔΔΔΔΔΔΔΔΑ",
   " ΔΔΔΔΔΔΔΔΔΔΔΔΔΔΑ",
   " ΔΔΔΔΔΔΔΔΔΔΔΔΔΔΑ",
   " ΔΔΔΔΔΔΔΔΔΔΔΔΔΔΑ",
   " ΔΔΔΔΔΔΔΔΔΔΔΔΔΔΑ",
   " ΔΔΔΔΔΔΔΔΔΔΔΔΔΔΑ",
   " ΔΔΔΔΔΔΔΔΔΔΔΔΔΔΑ",
   " ΔΔΔΔΔΔΔΔΔΔΔΔΔΔΑ",
   "ΑΑΑΑΑΑΑΑΑΑΑΑΑΑΑΑ"
  ],
  [
   "               Β",
   " ░    Ε        Α",
   "      Ε  ░    ΣΑ",
   " ѵ ѵΕ    ░Ε ϠΑ",
   "        ░   Ε ϠΑ",
   "    ШΕ     ΕϠϠΒ",
   " ΕΕΕΕΕΕ     ΕϠϠΑ",
   "        ░     ░Α",
   "         ░     Α",
   " ΕΕΕΕΕΕ  ΕΕΕΕΕΕΑ",
   "      Ε  Ε░    Β",
   "               Α",
   " ѵ ѵΕ  Εѵ ѵΑ",
   "      Ε  Ε     Α",
   "    ШΕ  Εф ░ ШΑ",
   "ΒΑΑΑΑΒΑΑΑΑΒΑΑΑΑΒ"
  ],
  [
   "               Β",
   "      Ε        Γ",
   "      Ε        Γ",
   "  ѵ  ѵΕ     Ε ΣΓ",
   "            Ε ϠΓ",
   "      Ε     ΕϠϠΒ",
   " ΕΕΕΕΕΕ     ΕϠϠΓ",
   "               Γ",
   "               Γ",
   " ΕΕΕΕΕΕ  ΕΕΕΕΕΕΓ",
   "      Ε  Ε     Β",
   "               Γ",
   "  ѵ  ѵΕ  Ε ѵ  ѵΓ",
   "      Ε  Ε     Γ",
   "      Ε  Ε     Γ",
   "ΒΓΓΓΓΒΓΓΓΓΒΓΓΓΓΒ"
  ],
  [
   "               Β",
   "      Ε     Ε  Γ",
   "      Ε     Ε  Γ",
   "      Ε     Ε  Γ",
   "      Ε     Ε ΣΓ",
   "      Ε     ΕϠϠΒ",
   " ΕΕΕΕΕΕ     ΕϠϠΓ",
   "               Γ",
   "               Γ",
   " ΕΕΕΕΕΕ  ΕΕΕΕΕΕΓ",
   "      Ε  Ε     Β",
   "      Ε  Ε     Γ",
   "      Ε  Ε     Γ",
   "      Ε  Ε     Γ",
   "      Ε  Ε     Γ",
   "ΒΓΓΓΓΒΓΓΓΓΒΓΓΓΓΒ"
  ],
  [
   "               Β",
   "      Ε     Ε  Α",
   "      Ε     Ε  Α",
   "   Ι  Ε   Ι Ε  Α",
   "      Ε     ΕϚ Α",
   "      Ε     Ε  Β",
   " ΕΕΕΕΕΕ     Ε  Α",
   "       Ι       Α",
   "        Ι      Α",
   " ΕΕΕΕΕΕ  ΕΕΕΕΕΕΑ",
   "      Ε  Ε     Β",
   "      Ε  Ε     Α",
   "   Ι  Ε  Ε Ι   Α",
   "      Ε  Ε     Α",
   "      Ε  Ε     Α",
   "ΒΑΑΑΑΒΑΑΑΑΒΑΑΑΑΒ"
  ],
  [
   "               Α",
   " ΔΔΔΔΔΔΔΔΔΔΔΔΔΔΑ",
   " ΔΔΔΔΔΔΔΔΔΔΔΔΔΔΑ",
   " ΔΔΔΔΔΔΔΔΔΔΔΔϚΔΑ",
   " ΔΔΔΔΔΔΔΔΔΔΔΔ  Α",
   " ΔΔΔΔΔΔΔΔΔΔΔΔ  Α",
   " ΔΔΔΔΔΔΔΔΔΔΔΔ  Α",
   " ΔΔΔΔΔΔΔΔΔΔΔΔΔΔΑ",
   " ΔΔΔΔΔΔΔΔΔΔΔΔΔΔΑ",
   " ΔΔΔΔΔΔΔΔΔΔΔΔΔΔΑ",
   " ΔΔΔΔΔΔΔΔΔΔΔΔΔΔΑ",
   " ΔΔΔΔΔΔΔΔΔΔΔΔΔΔΑ",
   " ΔΔΔΔΔΔΔΔΔΔΔΔΔΔΑ",
   " ΔΔΔΔΔΔΔΔΔΔΔΔΔΔΑ",
   " ΔΔΔΔΔΔΔΔΔΔΔΔΔΔΑ",
   "ΑΑΑΑΑΑΑΑΑΑΑΑΑΑΑΑ"
  ]
 ],
 "palette": {
  "palette": [
   {
    "char": "",
    "block": "refurbished_furniture:white_basin[facing=south]",
    "damaged": "minecraft:air"
   },
   {
    "char": "",
    "block": "hospitals:hospital_bed[facing=south]"
   }
  ]
 }
}