{
 "xsize": 16,
 "zsize": 16,
 "slices": [
  [
   "ΑΑΑΑΑΑΑΑΑΑΑΑΑΑΑΑ",
   "ΑΔΔΔΔΔΔΔΔΔΔΔΔΔΔ ",
   "ΑΔΔΔΔΔΔΔΔΔΔΔΔΔΔ ",
   "ΑΔΔΔΔΔΔΔΔΔΔΔΔ Δ ",
   "ΑΔΔΔΔΔΔΔΔΔΔΔΔ Δ ",
   "ΑΔΔΔΔΔΔΔΔΔΔΔΔΔΔ ",
   "ΑΔΔΔΔΔΔΔΔΔΔΔΔΔΔ ",
   "ΑΔΔΔΔΔΔΔΔΔΔΔΔΔΔ ",
   "ΑΔΔΔΔΔΔΔΔΔΔΔΔΔΔ ",
   "ΑΔΔΔΔΔΔΔΔΔΔΔΔΔΔ ",
   "ΑΔΔΔΔΔΔΔΔΔΔΔΔΔΔ ",
   "ΑΔΔΔΔΔΔΔΔΔΔΔΔΔΔ ",
   "ΑΔΔΔΔΔΔΔΔΔΔΔΔΔΔ ",
   "ΑΔΔΔΔΔΔΔΔΔΔΔΔΔΔ ",
   "ΑΔΔΔΔΔΔΔΔΔΔΔΔΔΔ ",
   "Α               "
  ],
  [
   "ΒΑΑΑΑΒΑΑΑΑΒΑΑΑΑΒ",
   "Α░    Ε░        ",
   "Α     Ε       Σ ",
   "Αѵ ѵΕ     Ε Ϡ ",
   "Α           Ε Ϡ ",
   "Βф   ШΕ     ΕϠϠ ",
   "ΑΕΕΕΕΕΕ     ΕϠϠ ",
   "Α          ░    ",
   "Α               ",
   "ΑΕΕΕΕΕΕ░ ΕΕΕΕΕΕ ",
   "Β     Ε ░Ε      ",
   "Α               ",
   "Αѵ ѵΕ ░Εѵ ѵ ",
   "Α     Ε  Ε   ░  ",
   "Αф   Ε  Εф   Ш ",
   "Β               "
  ],
  [
   "ΒΓΓΓΓΒΓΓΓΓΒΓΓΓΓΒ",
   "Γ     Ε         ",
   "Γ     Ε         ",
   "Γ ѵ  ѵΕ     Ε Σ ",
   "Γ           Ε Ϡ ",
   "Β     Ε     ΕϠϠ ",
   "ΓΕΕΕΕΕΕ     ΕϠϠ ",
   "Γ               ",
   "Γ               ",
   "ΓΕΕΕΕΕΕ  ΕΕΕΕΕΕ ",
   "Β     Ε  Ε      ",
   "Γ               ",
   "Γ ѵ  ѵΕ  Ε ѵ  ѵ ",
   "Γ     Ε  Ε      ",
   "Γ     Ε  Ε      ",
   "Β               "
  ],
  [
   "ΒΓΓΓΓΒΓΓΓΓΒΓΓΓΓΒ",
   "Γ     Ε     Ε   ",
   "Γ     Ε     Ε   ",
   "Γ     Ε     Ε   ",
   "Γ     Ε     Ε Σ ",
   "Β     Ε     ΕϠϠ ",
   "ΓΕΕΕΕΕΕ     ΕϠϠ ",
   "Γ               ",
   "Γ               ",
   "ΓΕΕΕΕΕΕ  ΕΕΕΕΕΕ ",
   "Β     Ε  Ε      ",
   "Γ     Ε  Ε      ",
   "Γ     Ε  Ε      ",
   "Γ     Ε  Ε      ",
   "Γ     Ε  Ε      ",
   "Β               "
  ],
  [
   "ΒΑΑΑΑΒΑΑΑΑΒΑΑΑΑΒ",
   "Α     Ε     Ε   ",
   "Α     Ε     Ε   ",
   "Α  Ι  Ε   Ι Ε   ",
   "Α     Ε     ΕϚ  ",
   "Β     Ε     Ε   ",
   "ΑΕΕΕΕΕΕ     Ε   ",
   "Α      Ι        ",
   "Α       Ι       ",
   "ΑΕΕΕΕΕΕ  ΕΕΕΕΕΕ ",
   "Β     Ε  Ε      ",
   "Α     Ε  Ε      ",
   "Α  Ι  Ε  Ε Ι    ",
   "Α     Ε  Ε      ",
   "Α     Ε  Ε      ",
   "Β               "
  ],
  [
   "ΑΑΑΑΑΑΑΑΑΑΑΑΑΑΑΑ",
   "ΑΔΔΔΔΔΔΔΔΔΔΔΔΔΔ ",
   "ΑΔΔΔΔΔΔΔΔΔΔΔΔΔΔ ",
   "ΑΔΔΔΔΔΔΔΔΔΔΔΔϚΔ ",
   "ΑΔΔΔΔΔΔΔΔΔΔΔΔ   ",
   "ΑΔΔΔΔΔΔΔΔΔΔΔΔ   ",
   "ΑΔΔΔΔΔΔΔΔΔΔΔΔ   ",
   "ΑΔΔΔΔΔΔΔΔΔΔΔΔΔΔ ",
   "ΑΔΔΔΔΔΔΔΔΔΔΔΔΔΔ ",
   "ΑΔΔΔΔΔΔΔΔΔΔΔΔΔΔ ",
   "ΑΔΔΔΔΔΔΔΔΔΔΔΔΔΔ ",
   "ΑΔΔΔΔΔΔΔΔΔΔΔΔΔΔ ",
   "ΑΔΔΔΔΔΔΔΔΔΔΔΔΔΔ ",
   "ΑΔΔΔΔΔΔΔΔΔΔΔΔΔΔ ",
   "ΑΔΔΔΔΔΔΔΔΔΔΔΔΔΔ ",
   "Α               "
  ]
 ],
 "palette": {
  "palette": [
   {
    "char": "",
    "block": "minecraft:chest[facing=west]",
    "loot": "zc_world:loot_house"
   },
   {
    "char": "",
    "block": "hospitals:hospital_bed[facing=south]"
   }
  ]
 }
}