{
  "xsize": 16,
  "zsize": 16,
  "slices": [
    [
      "一一一一一一一一一一一一一一一一",
      "丁丁丁丁丁丁丁丁丁丁丁丁丁丁丁一",
      "丁丁丁丁丁丁丁丁丁丁丁丁丁丁丁一",
      "丁丁丁丁丁丁丁丁丁丁丁丁丁丁丁一",
      "丁丁丁丁丁丁丁丁丁丁丁丁丁丁丁一",
      "丁丁丁丁丁丁丁丁丁丁丁丁丁丁丁一",
      "    丁丁丁丁丁丁丁丁丁丁丁一",
      "    丁丁丁丁丁丁丁丁丁丁丁一",
      "    丁丁丁丁丁丁丁丁丁丁丁一",
      "丁丁丁丁丁丁丁丁丁丁丁丁丁丁丁一",
      "丁丁丁丁丁丁丁丁丁丁丁丁丁丁丁一",
      "丁丁丁丁丁丁丁丁丁丁丁丁丁丁丁一",
      "丁丁丁丁丁丁丁丁丁丁丁丁丁丁丁一",
      "丁丁丁丁丁丁丁丁丁丁丁丁丁丁丁一",
      "一一一一一一一一一一一一一一一一",
      "   丂            "
    ],
    [
      "①①①①①①①①①①①①①①①①",
      "七 丄  丅 丄  七 丄  ①",
      "               ①",
      "丆万丆丆 丆万丆丆 丆万丆丆 ①",
      "               ①",
      "丈丈丈三           ①",
      "    上          ①",
      "    下丌不与 丌不与  丏①",
      "    丐          ①",
      "丈丈丈三           ①",
      "               ①",
      "丌不与   丌不与 丌不与  ①",
      "               ①",
      "               ①",
      "丑⑩⑩⑩⑩⑩⑩⑩⑩⑩⑩丑⑩⑩⑩①",
      "                "
    ],
    [
      "①⑨①①⑨①①⑨①①⑨①①丑①①",
      "               ①",
      "               ①",
      "               ⑨",
      "               ①",
      "               ①",
      "               ⑨",
      "              丏①",
      "               ①",
      "               ⑨",
      "               ①",
      "              丒①",
      "               ⑨",
      "               ①",
      "⑩⑩⑩丑⑩丑⑩⑩⑩⑩⑩丑⑩⑩⑩①",
      "                "
    ],
    [
      "①丑①①⑨①①⑨①①丑①①⑨①①",
      "              丒①",
      "               ①",
      "               丑",
      "               ①",
      "               ①",
      "               丑",
      "              丏①",
      "               ①",
      "               丑",
      "               ①",
      "              丏①",
      "               ⑨",
      "               ①",
      "⑩⑩丑⑩⑩⑩丑⑩⑩⑩⑩⑩⑩丑⑩①",
      "                "
    ],
    [
      "①①①①①①①①①①①①①①①①",
      " 专    且    丕  丒①",
      "               ①",
      "               ①",
      "               ①",
      "               ①",
      "              丒①",
      "               ①",
      "               ①",
      "               ①",
      "               ①",
      "               ①",
      "               ①",
      "               ①",
      "⑩⑩⑩丑⑩丑⑩丑⑩丑丑⑩⑩⑩⑩①",
      "                "
    ],
    [
      "①①①①①①①①①①①①①①①①",
      "              丏①",
      "               ①",
      "               ①",
      "               ①",
      "               ①",
      "               ①",
      "  世    世    世  ①",
      "               ①",
      "               ①",
      "               ①",
      "               ①",
      "               ①",
      "  丗            ①",
      "①①①①①①①①①①①①①①①①",
      "                "
    ]
  ],
  "palette": {
    "palette": [
      {
        "char": "一",
        "block": "minecraft:white_concrete"
      },
      {
        "char": "丁",
        "blocks": [
          {
            "random": 90,
            "block": "minecraft:polished_diorite"
          },
          {
            "random": 1000,
            "block": "minecraft:white_terracotta"
          }
        ]
      },
      {
        "char": "丂",
        "block": "minecraft:vine[north=true]"
      },
      {
        "char": "七",
        "block": "refurbished_furniture:light_fridge[facing=north]",
        "loot": "zc_world:loot_fridge"
      },
      {
        "char": "丄",
        "block": "refurbished_furniture:red_cooler[facing=north]",
        "loot": "zc_world:loot_padaria"
      },
      {
        "char": "丅",
        "block": "refurbished_furniture:light_stove[facing=north]"
      },
      {
        "char": "丆",
        "block": "handcrafted:oak_counter[counter=smooth_stone,facing=south,type=1]"
      },
      {
        "char": "万",
        "block": "refurbished_furniture:oak_drawer[facing=north]",
        "loot": "zc_world:loot_boteco"
      },
      {
        "char": "丈",
        "block": "minecraft:iron_bars[north=false,south=false,east=true,west=true]"
      },
      {
        "char": "三",
        "block": "minecraft:iron_bars[north=false,south=false,east=false,west=true]"
      },
      {
        "char": "上",
        "block": "minecraft:iron_bars[north=false,south=true,east=false,west=false]"
      },
      {
        "char": "下",
        "block": "minecraft:iron_bars[north=true,south=true,east=false,west=false]"
      },
      {
        "char": "丌",
        "block": "refurbished_furniture:birch_chair[facing=west,tucked=false]"
      },
      {
        "char": "不",
        "block": "refurbished_furniture:birch_table[north=false,south=false,east=false,west=false]"
      },
      {
        "char": "与",
        "blocks": [
          {
            "random": 77,
            "block": "refurbished_furniture:birch_chair[facing=east,tucked=false]"
          },
          {
            "random": 1000,
            "block": "zc_world:litter"
          }
        ]
      },
      {
        "char": "丏",
        "block": "minecraft:vine[east=true]"
      },
      {
        "char": "丐",
        "block": "minecraft:iron_bars[north=true,south=false,east=false,west=false]"
      },
      {
        "char": "丑",
        "blocks": [
          {
            "random": 58,
            "block": "minecraft:oak_planks"
          },
          {
            "random": 38,
            "block": "minecraft:spruce_planks"
          },
          {
            "random": 1000,
            "block": "minecraft:stripped_oak_log[axis=y]"
          }
        ]
      },
      {
        "char": "丒",
        "block": "immersive_weathering:ivy[down=false,east=true,north=false,south=false,up=false,west=false]"
      },
      {
        "char": "专",
        "block": "kubejs:sign_burger[facing=south]"
      },
      {
        "char": "且",
        "block": "kubejs:sign_acai[facing=south]"
      },
      {
        "char": "丕",
        "block": "kubejs:sign_prato_feito[facing=south]"
      },
      {
        "char": "世",
        "block": "refurbished_furniture:light_ceiling_light[face=ceiling,facing=north,powered=false]"
      },
      {
        "char": "丗",
        "block": "immersive_weathering:ivy[down=false,east=false,north=false,south=true,up=false,west=false]"
      }
    ]
  }
}
