{
  "xsize": 16,
  "zsize": 16,
  "slices": [
    [
      "一一一一一一一一一一一一一一一 ",
      "一丁丁丁丁丁丁丁丁丁丁丁丁丁一 ",
      "一丁丁丁丁丁丁丁丁丁丁丁丁丁一 ",
      "一丁丁丁丁丁丁丁丁丁丁丁丁丁一 ",
      "一丁丁丁丁丁丁丁丁丁丁丁丁丁一 ",
      "一丁丁丁丁丁丁丁丁丁丁丁丁丁一 ",
      "一丁丁丁丁丁丁丁丁丁丁丁丁丁一 ",
      "一丁丁丁丁丁丁丁丁丁丁丁丁丁一 ",
      "一丁丁丁丁丁丁丁丁丁丁丁丁丁一 ",
      "一丁丁丁丁丁丁丁丁丁丁丁丁丁一 ",
      "一丁丁丁丁丁丁丁丁丁丁丁丁丁一 ",
      "一丁丁丁丁丁丁丁丁丁丁丁丁丁一 ",
      "一丁丁丁丁丁   丁丁丁丁丁一丂",
      "一丁丁丁丁丁   丁丁丁丁丁一 ",
      "一丁丁丁丁丁   丁丁丁丁丁一 ",
      "一丁丁丁丁丁   丁丁丁丁丁一 "
    ],
    [
      "①①①①①①①①①①①①①①① ",
      "①      七      ⑩ ",
      "①  丄          ⑩ ",
      "①丅 丄       丆  ⑩ ",
      "①  万   丆   丈  三 ",
      "①上 丄   丈   下  ⑩ ",
      "①      下      ⑩ ",
      "①  丄       丆  ⑩ ",
      "①丅 丄   丆   丈  ⑩ ",
      "①  万   丈   下  ⑩ ",
      "①丌 丄   下      ⑩ ",
      "①     不与丏     ⑩ ",
      "①  丄 丐   丐    ⑩ ",
      "①丅 丄 丑   丑 丆  ⑩ ",
      "①  万 丑   丑 丈  ⑩ ",
      "①上 丄 丑   丑 下  三 "
    ],
    [
      "①①①⑨①①⑨①①⑨①①⑨①① ",
      "①      七   丒  ⑩ ",
      "三             ⑩ ",
      "①             ⑩ ",
      "①             三 ",
      "⑨             ⑩ ",
      "①             ⑩ ",
      "①             ⑩ ",
      "⑨             ⑩ ",
      "①             ⑩ ",
      "①             三 ",
      "⑨             ⑩ ",
      "①             三 ",
      "①             ⑩ ",
      "⑨             ⑩ ",
      "①             ⑩ "
    ],
    [
      "①①①三①①三①①三①①⑨①① ",
      "①丒     七   七  ⑩ ",
      "⑨             三 ",
      "①             ⑩ ",
      "①             ⑩ ",
      "三             ⑩ ",
      "①             ⑩ ",
      "①             ⑩ ",
      "⑨             ⑩ ",
      "①             三 ",
      "①             ⑩ ",
      "⑨             ⑩ ",
      "①             ⑩ ",
      "①             三 ",
      "三             ⑩ ",
      "①             ⑩ "
    ],
    [
      "①①①①①①①①①①①①①①① ",
      "①丒    丒       ⑩ ",
      "①             ⑩ ",
      "①             ⑩ ",
      "①专            ⑩ ",
      "①             三 ",
      "①             三 ",
      "①             ⑩ ",
      "①             三 ",
      "①且            ⑩ ",
      "①             三 ",
      "①             ⑩ ",
      "①             三 ",
      "①             ⑩ ",
      "①丕            ⑩ ",
      "①             ⑩ "
    ],
    [
      "①①①①①①①①①①①①①①① ",
      "①七            ① ",
      "①             ① ",
      "①      世      ① ",
      "①             ① ",
      "①             ① ",
      "①             ① ",
      "①             ① ",
      "①      世      ① ",
      "①             ① ",
      "①             ① ",
      "①             ① ",
      "①             ① ",
      "①      世     丗① ",
      "①             ① ",
      "①             ① "
    ]
  ],
  "palette": {
    "palette": [
      {
        "char": "一",
        "block": "minecraft:white_concrete"
      },
      {
        "char": "丁",
        "blocks": [
          {
            "random": 90,
            "block": "minecraft:polished_diorite"
          },
          {
            "random": 1000,
            "block": "minecraft:white_terracotta"
          }
        ]
      },
      {
        "char": "丂",
        "block": "minecraft:vine[west=true]"
      },
      {
        "char": "七",
        "block": "minecraft:vine[north=true]"
      },
      {
        "char": "丄",
        "block": "handcrafted:oak_counter[counter=smooth_stone,facing=east,type=1]"
      },
      {
        "char": "丅",
        "block": "refurbished_furniture:red_cooler[facing=west]",
        "loot": "zc_world:loot_padaria"
      },
      {
        "char": "丆",
        "blocks": [
          {
            "random": 77,
            "block": "refurbished_furniture:birch_chair[facing=north,tucked=false]"
          },
          {
            "random": 1000,
            "block": "zc_world:litter"
          }
        ]
      },
      {
        "char": "万",
        "block": "refurbished_furniture:oak_drawer[facing=west]",
        "loot": "zc_world:loot_boteco"
      },
      {
        "char": "丈",
        "block": "refurbished_furniture:birch_table[north=false,south=false,east=false,west=false]"
      },
      {
        "char": "三",
        "blocks": [
          {
            "random": 58,
            "block": "minecraft:oak_planks"
          },
          {
            "random": 38,
            "block": "minecraft:spruce_planks"
          },
          {
            "random": 1000,
            "block": "minecraft:stripped_oak_log[axis=y]"
          }
        ]
      },
      {
        "char": "上",
        "block": "refurbished_furniture:light_fridge[facing=west]",
        "loot": "zc_world:loot_fridge"
      },
      {
        "char": "下",
        "block": "refurbished_furniture:birch_chair[facing=south,tucked=false]"
      },
      {
        "char": "丌",
        "block": "refurbished_furniture:light_stove[facing=west]"
      },
      {
        "char": "不",
        "block": "minecraft:iron_bars[north=false,south=false,east=true,west=false]"
      },
      {
        "char": "与",
        "block": "minecraft:iron_bars[north=false,south=false,east=true,west=true]"
      },
      {
        "char": "丏",
        "block": "minecraft:iron_bars[north=false,south=false,east=false,west=true]"
      },
      {
        "char": "丐",
        "block": "minecraft:iron_bars[north=false,south=true,east=false,west=false]"
      },
      {
        "char": "丑",
        "block": "minecraft:iron_bars[north=true,south=true,east=false,west=false]"
      },
      {
        "char": "丒",
        "block": "immersive_weathering:ivy[down=false,east=false,north=true,south=false,up=false,west=false]"
      },
      {
        "char": "专",
        "block": "kubejs:sign_prato_feito[facing=east]"
      },
      {
        "char": "且",
        "block": "kubejs:sign_acai[facing=east]"
      },
      {
        "char": "丕",
        "block": "kubejs:sign_burger[facing=east]"
      },
      {
        "char": "世",
        "block": "refurbished_furniture:light_ceiling_light[face=ceiling,facing=west,powered=false]"
      },
      {
        "char": "丗",
        "block": "immersive_weathering:ivy[down=false,east=true,north=false,south=false,up=false,west=false]"
      }
    ]
  }
}
