{
  "xsize": 16,
  "zsize": 16,
  "slices": [
    [
      "            一   ",
      "丁丁丁丁丁丁丁丁丁丁丁丁丁丁丁丁",
      "丁丂丂丂丂丂丂丂丂丂丂丂丂丂丂丂",
      "丁丂丂丂丂丂丂丂丂丂丂丂丂丂丂丂",
      "丁丂丂丂丂丂丂丂丂丂丂丂丂丂丂丂",
      "丁丂丂丂丂丂丂丂丂丂丂丂丂丂丂丂",
      "丁丂丂丂丂丂丂丂丂丂丂丂丂丂丂丂",
      "丁丂丂丂丂丂丂丂丂丂丂丂    ",
      "丁丂丂丂丂丂丂丂丂丂丂丂    ",
      "丁丂丂丂丂丂丂丂丂丂丂丂    ",
      "丁丂丂丂丂丂丂丂丂丂丂丂丂丂丂丂",
      "丁丂丂丂丂丂丂丂丂丂丂丂丂丂丂丂",
      "丁丂丂丂丂丂丂丂丂丂丂丂丂丂丂丂",
      "丁丂丂丂丂丂丂丂丂丂丂丂丂丂丂丂",
      "丁丂丂丂丂丂丂丂丂丂丂丂丂丂丂丂",
      "丁丁丁丁丁丁丁丁丁丁丁丁丁丁丁丁"
    ],
    [
      "                ",
      "①⑩⑩⑩七⑩⑩⑩⑩⑩⑩⑩⑩⑩⑩七",
      "①               ",
      "①               ",
      "①  丄丅丆 丄丅丆   丄丅丆",
      "①               ",
      "①           万丈丈丈",
      "①          三    ",
      "①上  丄丅丆 丄丅丆下    ",
      "①          丌    ",
      "①           万丈丈丈",
      "①               ",
      "① 不不与不 不不与不 不不与不",
      "①               ",
      "①  丏 丐  丏 丑  丏 丐",
      "①①①①①①①①①①①①①①①①"
    ],
    [
      "                ",
      "①⑩⑩⑩七⑩⑩⑩⑩⑩七⑩七⑩⑩⑩",
      "①               ",
      "⑨               ",
      "①丒              ",
      "①               ",
      "⑨               ",
      "①               ",
      "①上              ",
      "⑨               ",
      "①               ",
      "①               ",
      "⑨               ",
      "①               ",
      "①               ",
      "①①七①①⑨①①⑨①①⑨①①⑨①"
    ],
    [
      "                ",
      "①⑩七⑩⑩⑩⑩⑩⑩七⑩⑩⑩七⑩⑩",
      "①               ",
      "⑨               ",
      "①上              ",
      "①               ",
      "七               ",
      "①               ",
      "①上              ",
      "七               ",
      "①               ",
      "①               ",
      "七               ",
      "①               ",
      "①丒              ",
      "①①⑨①①七①①⑨①①⑨①①七①"
    ],
    [
      "                ",
      "①⑩⑩⑩⑩七七⑩七⑩七⑩七⑩⑩⑩",
      "①               ",
      "①               ",
      "①               ",
      "①               ",
      "①               ",
      "①               ",
      "①               ",
      "①丒              ",
      "①               ",
      "①               ",
      "①               ",
      "①               ",
      "①丒  专    且    丕 ",
      "①①①①①①①①①①①①①①①①"
    ],
    [
      "                ",
      "①①①①①①①①①①①①①①①①",
      "①            世  ",
      "①               ",
      "①               ",
      "①               ",
      "①               ",
      "①               ",
      "①  丗    丗    丗  ",
      "①               ",
      "①               ",
      "①               ",
      "①               ",
      "①               ",
      "①上              ",
      "①①①①①①①①①①①①①①①①"
    ]
  ],
  "palette": {
    "palette": [
      {
        "char": "一",
        "block": "minecraft:vine[south=true]"
      },
      {
        "char": "丁",
        "block": "minecraft:white_concrete"
      },
      {
        "char": "丂",
        "blocks": [
          {
            "random": 90,
            "block": "minecraft:polished_diorite"
          },
          {
            "random": 1000,
            "block": "minecraft:white_terracotta"
          }
        ]
      },
      {
        "char": "七",
        "blocks": [
          {
            "random": 58,
            "block": "minecraft:oak_planks"
          },
          {
            "random": 38,
            "block": "minecraft:spruce_planks"
          },
          {
            "random": 1000,
            "block": "minecraft:stripped_oak_log[axis=y]"
          }
        ]
      },
      {
        "char": "丄",
        "blocks": [
          {
            "random": 77,
            "block": "refurbished_furniture:birch_chair[facing=west,tucked=false]"
          },
          {
            "random": 1000,
            "block": "zc_world:litter"
          }
        ]
      },
      {
        "char": "丅",
        "block": "refurbished_furniture:birch_table[north=false,south=false,east=false,west=false]"
      },
      {
        "char": "丆",
        "block": "refurbished_furniture:birch_chair[facing=east,tucked=false]"
      },
      {
        "char": "万",
        "block": "minecraft:iron_bars[north=false,south=false,east=true,west=false]"
      },
      {
        "char": "丈",
        "block": "minecraft:iron_bars[north=false,south=false,east=true,west=true]"
      },
      {
        "char": "三",
        "block": "minecraft:iron_bars[north=false,south=true,east=false,west=false]"
      },
      {
        "char": "上",
        "block": "minecraft:vine[west=true]"
      },
      {
        "char": "下",
        "block": "minecraft:iron_bars[north=true,south=true,east=false,west=false]"
      },
      {
        "char": "丌",
        "block": "minecraft:iron_bars[north=true,south=false,east=false,west=false]"
      },
      {
        "char": "不",
        "block": "handcrafted:oak_counter[counter=smooth_stone,facing=north,type=1]"
      },
      {
        "char": "与",
        "block": "refurbished_furniture:oak_drawer[facing=south]",
        "loot": "zc_world:loot_boteco"
      },
      {
        "char": "丏",
        "block": "refurbished_furniture:red_cooler[facing=south]",
        "loot": "zc_world:loot_padaria"
      },
      {
        "char": "丐",
        "block": "refurbished_furniture:light_fridge[facing=south]",
        "loot": "zc_world:loot_fridge"
      },
      {
        "char": "丑",
        "block": "refurbished_furniture:light_stove[facing=south]"
      },
      {
        "char": "丒",
        "block": "immersive_weathering:ivy[down=false,east=false,north=false,south=false,up=false,west=true]"
      },
      {
        "char": "专",
        "block": "kubejs:sign_prato_feito[facing=north]"
      },
      {
        "char": "且",
        "block": "kubejs:sign_acai[facing=north]"
      },
      {
        "char": "丕",
        "block": "kubejs:sign_burger[facing=north]"
      },
      {
        "char": "世",
        "block": "immersive_weathering:ivy[down=false,east=false,north=true,south=false,up=false,west=false]"
      },
      {
        "char": "丗",
        "block": "refurbished_furniture:light_ceiling_light[face=ceiling,facing=south,powered=false]"
      }
    ]
  }
}
